######TESTING REPORT######

Date: Sat Nov 27 14:45:04 CST 2021 

---UNITTEST---

test_dequip (tests.test_armor.ArmorTest) ... ok
test_details (tests.test_armor.ArmorTest) ... ok
test_equip (tests.test_armor.ArmorTest) ... ok
test_export (tests.test_armor.ArmorTest) ... FAIL
test_init (tests.test_armor.ArmorTest) ... ok
test_itemCopy (tests.test_armor.ArmorTest) ... ok
test_printToFile (tests.test_armor.ArmorTest) ... ok
test_str (tests.test_armor.ArmorTest) ... ok
test_details (tests.test_equipment.EquipmentTest) ... ok
test_export (tests.test_equipment.EquipmentTest) ... ok
test_init (tests.test_equipment.EquipmentTest) ... ok
test_printToFile (tests.test_equipment.EquipmentTest) ... ok
test_str (tests.test_equipment.EquipmentTest) ... ok

======================================================================
FAIL: test_export (tests.test_armor.ArmorTest)
----------------------------------------------------------------------
Traceback (most recent call last):
  File "/mnt/c/Users/jevin/OneDrive/Documents/CODING/Dev/FUNCLG/tests/test_armor.py", line 261, in test_export
    self.fail("Need to Create Test")
AssertionError: Need to Create Test

----------------------------------------------------------------------
Ran 13 tests in 0.257s

FAILED (failures=1)

---Flake 8----

./FUNCLG/core/armor.py:151:7: T101 fixme found (TODO)
./FUNCLG/core/armor.py:87:7: T101 fixme found (TODO)
./FUNCLG/core/equipment.py:60:11: T101 fixme found (TODO)
./FUNCLG/core/equipment.py:76:7: T101 fixme found (TODO)
4
