######TESTING REPORT######

Date: Thu Aug 26 20:36:03 CDT 2021 

---UNITTEST---

test_dequip (tests.test_armor.ArmorTest) ... FAIL
test_details (tests.test_armor.ArmorTest) ... FAIL
test_equip (tests.test_armor.ArmorTest)
Testing that the equip function for success ... FAIL
test_export (tests.test_armor.ArmorTest) ... FAIL
test_init (tests.test_armor.ArmorTest) ... ok
test_printToFile (tests.test_armor.ArmorTest)
Testing printToFile existance ... ok
test_str (tests.test_armor.ArmorTest)
Testing object print format ... FAIL
test_details (tests.test_equipment.EquipmentTest) ... ok
test_export1 (tests.test_equipment.EquipmentTest) ... ok
test_init (tests.test_equipment.EquipmentTest) ... ok
test_printToFile (tests.test_equipment.EquipmentTest) ... ok
test_str (tests.test_equipment.EquipmentTest) ... ok

======================================================================
FAIL: test_dequip (tests.test_armor.ArmorTest)
----------------------------------------------------------------------
Traceback (most recent call last):
  File "/mnt/c/Users/jevin/OneDrive/Documents/CODING/Dev/FUNCLG/FUNCLG/tests/test_armor.py", line 81, in test_dequip
    self.fail("Need to Create Test")
AssertionError: Need to Create Test

======================================================================
FAIL: test_details (tests.test_armor.ArmorTest)
----------------------------------------------------------------------
Traceback (most recent call last):
  File "/mnt/c/Users/jevin/OneDrive/Documents/CODING/Dev/FUNCLG/FUNCLG/tests/test_armor.py", line 94, in test_details
    self.fail("Need to Create Test")
AssertionError: Need to Create Test

======================================================================
FAIL: test_equip (tests.test_armor.ArmorTest)
Testing that the equip function for success
----------------------------------------------------------------------
Traceback (most recent call last):
  File "/mnt/c/Users/jevin/OneDrive/Documents/CODING/Dev/FUNCLG/FUNCLG/tests/test_armor.py", line 71, in test_equip
    self.fail("Need to Create Test")
AssertionError: Need to Create Test

======================================================================
FAIL: test_export (tests.test_armor.ArmorTest)
----------------------------------------------------------------------
Traceback (most recent call last):
  File "/mnt/c/Users/jevin/OneDrive/Documents/CODING/Dev/FUNCLG/FUNCLG/tests/test_armor.py", line 112, in test_export
    self.fail("Need to Create Test")
AssertionError: Need to Create Test

======================================================================
FAIL: test_str (tests.test_armor.ArmorTest)
Testing object print format
----------------------------------------------------------------------
Traceback (most recent call last):
  File "/mnt/c/Users/jevin/OneDrive/Documents/CODING/Dev/FUNCLG/FUNCLG/tests/test_armor.py", line 64, in test_str
    self.fail("Need to Create Test")
AssertionError: Need to Create Test

----------------------------------------------------------------------
Ran 12 tests in 0.009s

FAILED (failures=5)

---Flake 8----

./core/armor.py:46:7: T101 fixme found (TODO)
./core/armor.py:47:7: T101 fixme found (TODO)
./core/equipment.py:52:11: T101 fixme found (TODO)
./core/equipment.py:69:11: T101 fixme found (TODO)
./tests/test_armor.py:70:11: T101 fixme found (TODO)
./tests/test_armor.py:73:11: T101 fixme found (TODO)
./tests/test_armor.py:76:11: T101 fixme found (TODO)
./tests/test_armor.py:80:11: T101 fixme found (TODO)
./tests/test_armor.py:83:11: T101 fixme found (TODO)
./tests/test_armor.py:86:11: T101 fixme found (TODO)
./tests/test_armor.py:89:11: T101 fixme found (TODO)
./tests/test_armor.py:93:11: T101 fixme found (TODO)
./tests/test_armor.py:96:11: T101 fixme found (TODO)
./tests/test_armor.py:111:11: T101 fixme found (TODO)
./tests/test_armor.py:114:1: E302 expected 2 blank lines, found 1
15
